[0m16:14:40.819890 [debug] [MainThread]: Sending event: {'category': 'dbt', 'action': 'invocation', 'label': 'start', 'context': [<snowplow_tracker.self_describing_json.SelfDescribingJson object at 0x0000013D9A8F5A90>, <snowplow_tracker.self_describing_json.SelfDescribingJson object at 0x0000013D98A6D590>, <snowplow_tracker.self_describing_json.SelfDescribingJson object at 0x0000013D9BA37D90>]}


============================== 16:14:40.824066 | 543aae83-3ac6-4896-94fb-4611c70eac40 ==============================
[0m16:14:40.824066 [info ] [MainThread]: Running with dbt=1.9.3
[0m16:14:40.825100 [debug] [MainThread]: running dbt with arguments {'printer_width': '80', 'indirect_selection': 'eager', 'log_cache_events': 'False', 'write_json': 'True', 'partial_parse': 'True', 'cache_selected_only': 'False', 'warn_error': 'None', 'fail_fast': 'False', 'version_check': 'True', 'log_path': 'logs', 'debug': 'False', 'profiles_dir': 'C:\\Users\\KIIT\\.dbt', 'use_colors': 'True', 'use_experimental_parser': 'False', 'no_print': 'None', 'quiet': 'False', 'empty': 'None', 'warn_error_options': 'WarnErrorOptions(include=[], exclude=[])', 'static_parser': 'True', 'introspect': 'True', 'log_format': 'default', 'target_path': 'None', 'invocation_command': 'dbt init my-dbt-project', 'send_anonymous_usage_stats': 'True'}
[0m16:14:40.888228 [warn ] [MainThread]: [ConfigFolderDirectory]: Unable to parse logging event dictionary. Failed to parse dir field: expected string or bytes-like object, got 'WindowsPath'.. Dictionary: {'dir': WindowsPath('C:/Users/KIIT/.dbt')}
[0m16:14:40.888938 [info ] [MainThread]: Creating dbt configuration folder at 
[0m16:15:57.984648 [debug] [MainThread]: Starter project path: C:\Users\KIIT\AppData\Local\Programs\Python\Python313\Lib\site-packages\dbt\include\starter_project
[0m16:15:58.000795 [info ] [MainThread]: 
Your new dbt project "my_dbt_project" was created!

For more information on how to configure the profiles.yml file,
please consult the dbt documentation here:

  https://docs.getdbt.com/docs/configure-your-profile

One more thing:

Need help? Don't hesitate to reach out to us via GitHub issues or on Slack:

  https://community.getdbt.com/

Happy modeling!

[0m16:15:58.001417 [info ] [MainThread]: Setting up your profile.
[0m16:17:53.821374 [error] [MainThread]: Encountered an error:

[0m16:17:53.833591 [error] [MainThread]: Traceback (most recent call last):
  File "C:\Users\KIIT\AppData\Local\Programs\Python\Python313\Lib\site-packages\dbt\cli\requires.py", line 153, in wrapper
    result, success = func(*args, **kwargs)
                      ~~~~^^^^^^^^^^^^^^^^^
  File "C:\Users\KIIT\AppData\Local\Programs\Python\Python313\Lib\site-packages\dbt\cli\requires.py", line 103, in wrapper
    return func(*args, **kwargs)
  File "C:\Users\KIIT\AppData\Local\Programs\Python\Python313\Lib\site-packages\dbt\cli\main.py", line 477, in init
    results = task.run()
  File "C:\Users\KIIT\AppData\Local\Programs\Python\Python313\Lib\site-packages\dbt\task\init.py", line 346, in run
    self.setup_profile(profile_name)
    ~~~~~~~~~~~~~~~~~~^^^^^^^^^^^^^^
  File "C:\Users\KIIT\AppData\Local\Programs\Python\Python313\Lib\site-packages\dbt\task\init.py", line 262, in setup_profile
    self.create_profile_from_target(adapter, profile_name=profile_name)
    ~~~~~~~~~~~~~~~~~~~~~~~~~~~~~~~^^^^^^^^^^^^^^^^^^^^^^^^^^^^^^^^^^^^
  File "C:\Users\KIIT\AppData\Local\Programs\Python\Python313\Lib\site-packages\dbt\task\init.py", line 179, in create_profile_from_target
    self.create_profile_from_profile_template(profile_template, profile_name)
    ~~~~~~~~~~~~~~~~~~~~~~~~~~~~~~~~~~~~~~~~~^^^^^^^^^^^^^^^^^^^^^^^^^^^^^^^^
  File "C:\Users\KIIT\AppData\Local\Programs\Python\Python313\Lib\site-packages\dbt\task\init.py", line 163, in create_profile_from_profile_template
    target = self.generate_target_from_input(prompts, initial_target)
  File "C:\Users\KIIT\AppData\Local\Programs\Python\Python313\Lib\site-packages\dbt\task\init.py", line 129, in generate_target_from_input
    target[key] = click.prompt(
                  ~~~~~~~~~~~~^
        text, default=default, hide_input=hide_input, type=type
        ^^^^^^^^^^^^^^^^^^^^^^^^^^^^^^^^^^^^^^^^^^^^^^^^^^^^^^^
    )
    ^
  File "C:\Users\KIIT\AppData\Local\Programs\Python\Python313\Lib\site-packages\click\termui.py", line 164, in prompt
    value = prompt_func(prompt)
  File "C:\Users\KIIT\AppData\Local\Programs\Python\Python313\Lib\site-packages\click\termui.py", line 147, in prompt_func
    raise Abort() from None
click.exceptions.Abort

[0m16:17:53.835641 [debug] [MainThread]: Command `dbt init` failed at 16:17:53.835327 after 193.18 seconds
[0m16:17:53.836306 [debug] [MainThread]: Sending event: {'category': 'dbt', 'action': 'invocation', 'label': 'end', 'context': [<snowplow_tracker.self_describing_json.SelfDescribingJson object at 0x0000013DBCA15350>, <snowplow_tracker.self_describing_json.SelfDescribingJson object at 0x0000013DBC9FAD50>, <snowplow_tracker.self_describing_json.SelfDescribingJson object at 0x0000013DBC9A5AE0>]}
[0m16:17:53.836663 [debug] [MainThread]: Flushing usage events
[0m16:17:55.287615 [debug] [MainThread]: An error was encountered while trying to flush usage events
[0m16:18:21.592615 [debug] [MainThread]: Sending event: {'category': 'dbt', 'action': 'invocation', 'label': 'start', 'context': [<snowplow_tracker.self_describing_json.SelfDescribingJson object at 0x000002898DC15A90>, <snowplow_tracker.self_describing_json.SelfDescribingJson object at 0x000002898BD7D590>, <snowplow_tracker.self_describing_json.SelfDescribingJson object at 0x000002898ED57D90>]}


============================== 16:18:21.596826 | 52f73e49-4a3c-4d83-93ed-5082591b9bcd ==============================
[0m16:18:21.596826 [info ] [MainThread]: Running with dbt=1.9.3
[0m16:18:21.598188 [debug] [MainThread]: running dbt with arguments {'printer_width': '80', 'indirect_selection': 'eager', 'log_cache_events': 'False', 'write_json': 'True', 'partial_parse': 'True', 'cache_selected_only': 'False', 'profiles_dir': 'C:\\Users\\KIIT\\.dbt', 'version_check': 'True', 'fail_fast': 'False', 'log_path': 'logs', 'warn_error': 'None', 'debug': 'False', 'use_colors': 'True', 'use_experimental_parser': 'False', 'no_print': 'None', 'quiet': 'False', 'empty': 'None', 'log_format': 'default', 'introspect': 'True', 'warn_error_options': 'WarnErrorOptions(include=[], exclude=[])', 'invocation_command': 'dbt init my_dbt_project', 'target_path': 'None', 'static_parser': 'True', 'send_anonymous_usage_stats': 'True'}
[0m16:18:21.613090 [info ] [MainThread]: A project called my_dbt_project already exists here.
[0m16:18:21.614699 [debug] [MainThread]: Command `dbt init` succeeded at 16:18:21.614497 after 0.17 seconds
[0m16:18:21.615087 [debug] [MainThread]: Sending event: {'category': 'dbt', 'action': 'invocation', 'label': 'end', 'context': [<snowplow_tracker.self_describing_json.SelfDescribingJson object at 0x000002898ED6E8B0>, <snowplow_tracker.self_describing_json.SelfDescribingJson object at 0x000002898EDF3650>, <snowplow_tracker.self_describing_json.SelfDescribingJson object at 0x000002898EC0DAE0>]}
[0m16:18:21.615412 [debug] [MainThread]: Flushing usage events
[0m16:18:22.690922 [debug] [MainThread]: An error was encountered while trying to flush usage events
[0m16:39:55.059530 [debug] [MainThread]: Sending event: {'category': 'dbt', 'action': 'invocation', 'label': 'start', 'context': [<snowplow_tracker.self_describing_json.SelfDescribingJson object at 0x0000017604DF5A90>, <snowplow_tracker.self_describing_json.SelfDescribingJson object at 0x0000017602F5D590>, <snowplow_tracker.self_describing_json.SelfDescribingJson object at 0x0000017605F47D90>]}


============================== 16:39:55.066515 | b5fa509c-af61-4c0f-b02b-72b28d0e179a ==============================
[0m16:39:55.066515 [info ] [MainThread]: Running with dbt=1.9.3
[0m16:39:55.067695 [debug] [MainThread]: running dbt with arguments {'printer_width': '80', 'indirect_selection': 'eager', 'write_json': 'True', 'log_cache_events': 'False', 'partial_parse': 'True', 'cache_selected_only': 'False', 'warn_error': 'None', 'debug': 'False', 'profiles_dir': 'C:\\Users\\KIIT\\.dbt', 'log_path': 'logs', 'version_check': 'True', 'fail_fast': 'False', 'use_colors': 'True', 'use_experimental_parser': 'False', 'no_print': 'None', 'quiet': 'False', 'empty': 'None', 'warn_error_options': 'WarnErrorOptions(include=[], exclude=[])', 'introspect': 'True', 'static_parser': 'True', 'log_format': 'default', 'target_path': 'None', 'invocation_command': 'dbt debug', 'send_anonymous_usage_stats': 'True'}
[0m16:39:55.086215 [info ] [MainThread]: dbt version: 1.9.3
[0m16:39:55.086810 [info ] [MainThread]: python version: 3.13.2
[0m16:39:55.087304 [info ] [MainThread]: python path: C:\Users\KIIT\AppData\Local\Programs\Python\Python313\python.exe
[0m16:39:55.087691 [info ] [MainThread]: os info: Windows-11-10.0.22631-SP0
[0m16:39:55.935335 [info ] [MainThread]: Using profiles dir at C:\Users\KIIT\.dbt
[0m16:39:55.936133 [info ] [MainThread]: Using profiles.yml file at C:\Users\KIIT\.dbt\profiles.yml
[0m16:39:55.937045 [info ] [MainThread]: Using dbt_project.yml file at C:\Users\KIIT\Downloads\my-dbt-project\dbt_project.yml
[0m16:39:55.938810 [info ] [MainThread]: adapter type: snowflake
[0m16:39:55.939679 [info ] [MainThread]: adapter version: 1.9.2
[0m16:39:55.940204 [info ] [MainThread]: Configuration:
[0m16:39:55.940586 [info ] [MainThread]:   profiles.yml file [[32mOK found and valid[0m]
[0m16:39:55.940973 [info ] [MainThread]:   dbt_project.yml file [[31mERROR not found[0m]
[0m16:39:55.941346 [info ] [MainThread]: Required dependencies:
[0m16:39:55.941757 [debug] [MainThread]: Executing "git --help"
[0m16:39:55.986536 [debug] [MainThread]: STDOUT: "b"usage: git [-v | --version] [-h | --help] [-C <path>] [-c <name>=<value>]\n           [--exec-path[=<path>]] [--html-path] [--man-path] [--info-path]\n           [-p | --paginate | -P | --no-pager] [--no-replace-objects] [--no-lazy-fetch]\n           [--no-optional-locks] [--no-advice] [--bare] [--git-dir=<path>]\n           [--work-tree=<path>] [--namespace=<name>] [--config-env=<name>=<envvar>]\n           <command> [<args>]\n\nThese are common Git commands used in various situations:\n\nstart a working area (see also: git help tutorial)\n   clone      Clone a repository into a new directory\n   init       Create an empty Git repository or reinitialize an existing one\n\nwork on the current change (see also: git help everyday)\n   add        Add file contents to the index\n   mv         Move or rename a file, a directory, or a symlink\n   restore    Restore working tree files\n   rm         Remove files from the working tree and from the index\n\nexamine the history and state (see also: git help revisions)\n   bisect     Use binary search to find the commit that introduced a bug\n   diff       Show changes between commits, commit and working tree, etc\n   grep       Print lines matching a pattern\n   log        Show commit logs\n   show       Show various types of objects\n   status     Show the working tree status\n\ngrow, mark and tweak your common history\n   backfill   Download missing objects in a partial clone\n   branch     List, create, or delete branches\n   commit     Record changes to the repository\n   merge      Join two or more development histories together\n   rebase     Reapply commits on top of another base tip\n   reset      Reset current HEAD to the specified state\n   switch     Switch branches\n   tag        Create, list, delete or verify a tag object signed with GPG\n\ncollaborate (see also: git help workflows)\n   fetch      Download objects and refs from another repository\n   pull       Fetch from and integrate with another repository or a local branch\n   push       Update remote refs along with associated objects\n\n'git help -a' and 'git help -g' list available subcommands and some\nconcept guides. See 'git help <command>' or 'git help <concept>'\nto read about a specific subcommand or concept.\nSee 'git help git' for an overview of the system.\n""
[0m16:39:55.986965 [debug] [MainThread]: STDERR: "b''"
[0m16:39:55.987352 [info ] [MainThread]:  - git [[32mOK found[0m]

[0m16:39:55.987913 [info ] [MainThread]: Connection:
[0m16:39:55.988644 [info ] [MainThread]:   account: https://app.snowflake.com/alation/alation-partner-aws-us-west-2/#/data/databases/LOGAN-DATA
[0m16:39:55.989189 [info ] [MainThread]:   user: LD_USER
[0m16:39:55.989513 [info ] [MainThread]:   database: LOGAN_DATA
[0m16:39:55.990039 [info ] [MainThread]:   warehouse: LOAD_WH
[0m16:39:55.990590 [info ] [MainThread]:   role: LOGAN_DATA_ROLE
[0m16:39:55.991327 [info ] [MainThread]:   schema: Navanita_fivetran_dbt
[0m16:39:55.992741 [info ] [MainThread]:   authenticator: None
[0m16:39:55.993227 [info ] [MainThread]:   oauth_client_id: None
[0m16:39:55.993650 [info ] [MainThread]:   query_tag: None
[0m16:39:55.994008 [info ] [MainThread]:   client_session_keep_alive: False
[0m16:39:55.994377 [info ] [MainThread]:   host: None
[0m16:39:55.994737 [info ] [MainThread]:   port: None
[0m16:39:55.995090 [info ] [MainThread]:   proxy_host: None
[0m16:39:55.995470 [info ] [MainThread]:   proxy_port: None
[0m16:39:55.995818 [info ] [MainThread]:   protocol: None
[0m16:39:55.996159 [info ] [MainThread]:   connect_retries: 1
[0m16:39:55.996510 [info ] [MainThread]:   connect_timeout: None
[0m16:39:55.996807 [info ] [MainThread]:   retry_on_database_errors: False
[0m16:39:55.997081 [info ] [MainThread]:   retry_all: False
[0m16:39:55.997345 [info ] [MainThread]:   insecure_mode: False
[0m16:39:55.997773 [info ] [MainThread]:   reuse_connections: True
[0m16:39:55.998587 [info ] [MainThread]: Registered adapter: snowflake=1.9.2
[0m16:39:56.285877 [debug] [MainThread]: Acquiring new snowflake connection 'debug'
[0m16:39:56.351358 [debug] [MainThread]: Using snowflake connection "debug"
[0m16:39:56.351711 [debug] [MainThread]: On debug: select 1 as id
[0m16:39:56.351936 [debug] [MainThread]: Opening a new connection, currently in state init
[0m16:42:02.206809 [error] [MainThread]: Encountered an error:

[0m16:42:02.233043 [error] [MainThread]: Traceback (most recent call last):
  File "C:\Users\KIIT\AppData\Local\Programs\Python\Python313\Lib\site-packages\snowflake\connector\vendored\urllib3\connection.py", line 174, in _new_conn
    conn = connection.create_connection(
        (self._dns_host, self.port), self.timeout, **extra_kw
    )
  File "C:\Users\KIIT\AppData\Local\Programs\Python\Python313\Lib\site-packages\snowflake\connector\vendored\urllib3\util\connection.py", line 79, in create_connection
    for res in socket.getaddrinfo(host, port, family, socket.SOCK_STREAM):
               ~~~~~~~~~~~~~~~~~~^^^^^^^^^^^^^^^^^^^^^^^^^^^^^^^^^^^^^^^^
  File "C:\Users\KIIT\AppData\Local\Programs\Python\Python313\Lib\socket.py", line 977, in getaddrinfo
    for res in _socket.getaddrinfo(host, port, family, type, proto, flags):
               ~~~~~~~~~~~~~~~~~~~^^^^^^^^^^^^^^^^^^^^^^^^^^^^^^^^^^^^^^^^
socket.gaierror: [Errno 11001] getaddrinfo failed

During handling of the above exception, another exception occurred:

Traceback (most recent call last):
  File "C:\Users\KIIT\AppData\Local\Programs\Python\Python313\Lib\site-packages\dbt\cli\requires.py", line 153, in wrapper
    result, success = func(*args, **kwargs)
                      ~~~~^^^^^^^^^^^^^^^^^
  File "C:\Users\KIIT\AppData\Local\Programs\Python\Python313\Lib\site-packages\dbt\cli\requires.py", line 103, in wrapper
    return func(*args, **kwargs)
  File "C:\Users\KIIT\AppData\Local\Programs\Python\Python313\Lib\site-packages\dbt\cli\main.py", line 414, in debug
    results = task.run()
  File "C:\Users\KIIT\AppData\Local\Programs\Python\Python313\Lib\site-packages\dbt\task\debug.py", line 144, in run
    connection_status = self.test_connection()
  File "C:\Users\KIIT\AppData\Local\Programs\Python\Python313\Lib\site-packages\dbt\task\debug.py", line 465, in test_connection
    connection_result = self.attempt_connection(self.profile)
  File "C:\Users\KIIT\AppData\Local\Programs\Python\Python313\Lib\site-packages\dbt\task\debug.py", line 443, in attempt_connection
    adapter.debug_query()
    ~~~~~~~~~~~~~~~~~~~^^
  File "C:\Users\KIIT\AppData\Local\Programs\Python\Python313\Lib\site-packages\dbt\adapters\snowflake\impl.py", line 436, in debug_query
    self.execute("select 1 as id")
    ~~~~~~~~~~~~^^^^^^^^^^^^^^^^^^
  File "C:\Users\KIIT\AppData\Local\Programs\Python\Python313\Lib\site-packages\dbt\adapters\base\impl.py", line 404, in execute
    return self.connections.execute(sql=sql, auto_begin=auto_begin, fetch=fetch, limit=limit)
           ~~~~~~~~~~~~~~~~~~~~~~~~^^^^^^^^^^^^^^^^^^^^^^^^^^^^^^^^^^^^^^^^^^^^^^^^^^^^^^^^^^
  File "C:\Users\KIIT\AppData\Local\Programs\Python\Python313\Lib\site-packages\dbt\adapters\snowflake\connections.py", line 514, in execute
    _, cursor = self.add_query(sql, auto_begin)
                ~~~~~~~~~~~~~~^^^^^^^^^^^^^^^^^
  File "C:\Users\KIIT\AppData\Local\Programs\Python\Python313\Lib\site-packages\dbt\adapters\snowflake\connections.py", line 551, in add_query
    connection, cursor = self._add_standard_queries(
                         ~~~~~~~~~~~~~~~~~~~~~~~~~~^
        stripped_queries,
        ^^^^^^^^^^^^^^^^^
    ...<2 lines>...
        abridge_sql_log=abridge_sql_log,
        ^^^^^^^^^^^^^^^^^^^^^^^^^^^^^^^^
    )
    ^
  File "C:\Users\KIIT\AppData\Local\Programs\Python\Python313\Lib\site-packages\dbt\adapters\snowflake\connections.py", line 607, in _add_standard_queries
    connection, cursor = self.add_standard_query(query, **kwargs)
                         ~~~~~~~~~~~~~~~~~~~~~~~^^^^^^^^^^^^^^^^^
  File "C:\Users\KIIT\AppData\Local\Programs\Python\Python313\Lib\site-packages\dbt\adapters\snowflake\connections.py", line 525, in add_standard_query
    return super().add_query(self._add_query_comment(sql), **kwargs)
           ~~~~~~~~~~~~~~~~~^^^^^^^^^^^^^^^^^^^^^^^^^^^^^^^^^^^^^^^^
  File "C:\Users\KIIT\AppData\Local\Programs\Python\Python313\Lib\site-packages\dbt\adapters\sql\connections.py", line 146, in add_query
    cursor = connection.handle.cursor()
             ^^^^^^^^^^^^^^^^^
  File "C:\Users\KIIT\AppData\Local\Programs\Python\Python313\Lib\site-packages\dbt\adapters\contracts\connection.py", line 96, in handle
    self._handle.resolve(self)
    ~~~~~~~~~~~~~~~~~~~~^^^^^^
  File "C:\Users\KIIT\AppData\Local\Programs\Python\Python313\Lib\site-packages\dbt\adapters\contracts\connection.py", line 120, in resolve
    return self.opener(connection)
           ~~~~~~~~~~~^^^^^^^^^^^^
  File "C:\Users\KIIT\AppData\Local\Programs\Python\Python313\Lib\site-packages\dbt\adapters\snowflake\connections.py", line 420, in open
    return cls.retry_connection(
           ~~~~~~~~~~~~~~~~~~~~^
        connection,
        ^^^^^^^^^^^
    ...<4 lines>...
        retryable_exceptions=retryable_exceptions,
        ^^^^^^^^^^^^^^^^^^^^^^^^^^^^^^^^^^^^^^^^^^
    )
    ^
  File "C:\Users\KIIT\AppData\Local\Programs\Python\Python313\Lib\site-packages\dbt\adapters\base\connections.py", line 237, in retry_connection
    connection.handle = connect()
                        ~~~~~~~^^
  File "C:\Users\KIIT\AppData\Local\Programs\Python\Python313\Lib\site-packages\dbt\adapters\snowflake\connections.py", line 380, in connect
    handle = snowflake.connector.connect(
        account=creds.account,
    ...<9 lines>...
        **creds.auth_args(),
    )
  File "C:\Users\KIIT\AppData\Local\Programs\Python\Python313\Lib\site-packages\snowflake\connector\__init__.py", line 55, in Connect
    return SnowflakeConnection(**kwargs)
  File "C:\Users\KIIT\AppData\Local\Programs\Python\Python313\Lib\site-packages\snowflake\connector\connection.py", line 466, in __init__
    self.connect(**kwargs)
    ~~~~~~~~~~~~^^^^^^^^^^
  File "C:\Users\KIIT\AppData\Local\Programs\Python\Python313\Lib\site-packages\snowflake\connector\connection.py", line 793, in connect
    self.__open_connection()
    ~~~~~~~~~~~~~~~~~~~~~~^^
  File "C:\Users\KIIT\AppData\Local\Programs\Python\Python313\Lib\site-packages\snowflake\connector\connection.py", line 1124, in __open_connection
    self.authenticate_with_retry(self.auth_class)
    ~~~~~~~~~~~~~~~~~~~~~~~~~~~~^^^^^^^^^^^^^^^^^
  File "C:\Users\KIIT\AppData\Local\Programs\Python\Python313\Lib\site-packages\snowflake\connector\connection.py", line 1424, in authenticate_with_retry
    self._authenticate(auth_instance)
    ~~~~~~~~~~~~~~~~~~^^^^^^^^^^^^^^^
  File "C:\Users\KIIT\AppData\Local\Programs\Python\Python313\Lib\site-packages\snowflake\connector\connection.py", line 1452, in _authenticate
    auth.authenticate(
    ~~~~~~~~~~~~~~~~~^
        auth_instance=auth_instance,
        ^^^^^^^^^^^^^^^^^^^^^^^^^^^^
    ...<10 lines>...
        session_parameters=self._session_parameters,
        ^^^^^^^^^^^^^^^^^^^^^^^^^^^^^^^^^^^^^^^^^^^^
    )
    ^
  File "C:\Users\KIIT\AppData\Local\Programs\Python\Python313\Lib\site-packages\snowflake\connector\auth\_auth.py", line 270, in authenticate
    ret = self._rest._post_request(
        url,
    ...<2 lines>...
        socket_timeout=auth_instance._socket_timeout,
    )
  File "C:\Users\KIIT\AppData\Local\Programs\Python\Python313\Lib\site-packages\snowflake\connector\network.py", line 750, in _post_request
    ret = self.fetch(
        "post",
    ...<7 lines>...
        socket_timeout=socket_timeout,
    )
  File "C:\Users\KIIT\AppData\Local\Programs\Python\Python313\Lib\site-packages\snowflake\connector\network.py", line 865, in fetch
    ret = self._request_exec_wrapper(
        session, method, full_url, headers, data, retry_ctx, **kwargs
    )
  File "C:\Users\KIIT\AppData\Local\Programs\Python\Python313\Lib\site-packages\snowflake\connector\network.py", line 915, in _request_exec_wrapper
    return_object = self._request_exec(
        session=session,
    ...<6 lines>...
        **kwargs,
    )
  File "C:\Users\KIIT\AppData\Local\Programs\Python\Python313\Lib\site-packages\snowflake\connector\network.py", line 1082, in _request_exec
    raw_ret = session.request(
        method=method,
    ...<6 lines>...
        auth=SnowflakeAuth(token),
    )
  File "C:\Users\KIIT\AppData\Local\Programs\Python\Python313\Lib\site-packages\snowflake\connector\vendored\requests\sessions.py", line 589, in request
    resp = self.send(prep, **send_kwargs)
  File "C:\Users\KIIT\AppData\Local\Programs\Python\Python313\Lib\site-packages\snowflake\connector\vendored\requests\sessions.py", line 703, in send
    r = adapter.send(request, **kwargs)
  File "C:\Users\KIIT\AppData\Local\Programs\Python\Python313\Lib\site-packages\snowflake\connector\vendored\requests\adapters.py", line 486, in send
    resp = conn.urlopen(
        method=request.method,
    ...<9 lines>...
        chunked=chunked,
    )
  File "C:\Users\KIIT\AppData\Local\Programs\Python\Python313\Lib\site-packages\snowflake\connector\vendored\urllib3\connectionpool.py", line 715, in urlopen
    httplib_response = self._make_request(
        conn,
    ...<5 lines>...
        chunked=chunked,
    )
  File "C:\Users\KIIT\AppData\Local\Programs\Python\Python313\Lib\site-packages\snowflake\connector\vendored\urllib3\connectionpool.py", line 404, in _make_request
    self._validate_conn(conn)
    ~~~~~~~~~~~~~~~~~~~^^^^^^
  File "C:\Users\KIIT\AppData\Local\Programs\Python\Python313\Lib\site-packages\snowflake\connector\vendored\urllib3\connectionpool.py", line 1058, in _validate_conn
    conn.connect()
    ~~~~~~~~~~~~^^
  File "C:\Users\KIIT\AppData\Local\Programs\Python\Python313\Lib\site-packages\snowflake\connector\vendored\urllib3\connection.py", line 363, in connect
    self.sock = conn = self._new_conn()
                       ~~~~~~~~~~~~~~^^
  File "C:\Users\KIIT\AppData\Local\Programs\Python\Python313\Lib\site-packages\snowflake\connector\vendored\urllib3\connection.py", line 187, in _new_conn
    self, "Failed to establish a new connection: %s" % e
          ~~~~~~~~~~~~~~~~~~~~~~~~~~~~~~~~~~~~~~~~~~~^~~
KeyboardInterrupt

[0m16:42:02.237211 [debug] [MainThread]: Command `dbt debug` failed at 16:42:02.236896 after 127.36 seconds
[0m16:42:02.237740 [debug] [MainThread]: Connection 'debug' was properly closed.
[0m16:42:02.238303 [debug] [MainThread]: Sending event: {'category': 'dbt', 'action': 'invocation', 'label': 'end', 'context': [<snowplow_tracker.self_describing_json.SelfDescribingJson object at 0x00000176272CD5B0>, <snowplow_tracker.self_describing_json.SelfDescribingJson object at 0x000001762733CEF0>, <snowplow_tracker.self_describing_json.SelfDescribingJson object at 0x0000017626ED79B0>]}
[0m16:42:02.238927 [debug] [MainThread]: Flushing usage events
[0m16:42:03.618040 [debug] [MainThread]: An error was encountered while trying to flush usage events
[0m16:42:08.836329 [debug] [MainThread]: Sending event: {'category': 'dbt', 'action': 'invocation', 'label': 'start', 'context': [<snowplow_tracker.self_describing_json.SelfDescribingJson object at 0x000001D0C85E5A90>, <snowplow_tracker.self_describing_json.SelfDescribingJson object at 0x000001D0C675D590>, <snowplow_tracker.self_describing_json.SelfDescribingJson object at 0x000001D0C9727D90>]}


============================== 16:42:08.840968 | beb62b87-1fb0-4a9d-b8cb-f3e29545651f ==============================
[0m16:42:08.840968 [info ] [MainThread]: Running with dbt=1.9.3
[0m16:42:08.841689 [debug] [MainThread]: running dbt with arguments {'printer_width': '80', 'indirect_selection': 'eager', 'write_json': 'True', 'log_cache_events': 'False', 'partial_parse': 'True', 'cache_selected_only': 'False', 'warn_error': 'None', 'version_check': 'True', 'profiles_dir': 'C:\\Users\\KIIT\\.dbt', 'log_path': 'logs', 'debug': 'False', 'fail_fast': 'False', 'use_colors': 'True', 'use_experimental_parser': 'False', 'empty': 'None', 'quiet': 'False', 'no_print': 'None', 'warn_error_options': 'WarnErrorOptions(include=[], exclude=[])', 'introspect': 'True', 'log_format': 'default', 'static_parser': 'True', 'target_path': 'None', 'invocation_command': 'dbt debug', 'send_anonymous_usage_stats': 'True'}
[0m16:42:08.857741 [info ] [MainThread]: dbt version: 1.9.3
[0m16:42:08.858597 [info ] [MainThread]: python version: 3.13.2
[0m16:42:08.859449 [info ] [MainThread]: python path: C:\Users\KIIT\AppData\Local\Programs\Python\Python313\python.exe
[0m16:42:08.860045 [info ] [MainThread]: os info: Windows-11-10.0.22631-SP0
[0m16:42:09.539810 [info ] [MainThread]: Using profiles dir at C:\Users\KIIT\.dbt
[0m16:42:09.540556 [info ] [MainThread]: Using profiles.yml file at C:\Users\KIIT\.dbt\profiles.yml
[0m16:42:09.541299 [info ] [MainThread]: Using dbt_project.yml file at C:\Users\KIIT\Downloads\my-dbt-project\dbt_project.yml
[0m16:42:09.542630 [info ] [MainThread]: adapter type: snowflake
[0m16:42:09.543153 [info ] [MainThread]: adapter version: 1.9.2
[0m16:42:09.543776 [info ] [MainThread]: Configuration:
[0m16:42:09.544934 [info ] [MainThread]:   profiles.yml file [[32mOK found and valid[0m]
[0m16:42:09.545838 [info ] [MainThread]:   dbt_project.yml file [[31mERROR not found[0m]
[0m16:42:09.546363 [info ] [MainThread]: Required dependencies:
[0m16:42:09.546793 [debug] [MainThread]: Executing "git --help"
[0m16:42:09.582122 [debug] [MainThread]: STDOUT: "b"usage: git [-v | --version] [-h | --help] [-C <path>] [-c <name>=<value>]\n           [--exec-path[=<path>]] [--html-path] [--man-path] [--info-path]\n           [-p | --paginate | -P | --no-pager] [--no-replace-objects] [--no-lazy-fetch]\n           [--no-optional-locks] [--no-advice] [--bare] [--git-dir=<path>]\n           [--work-tree=<path>] [--namespace=<name>] [--config-env=<name>=<envvar>]\n           <command> [<args>]\n\nThese are common Git commands used in various situations:\n\nstart a working area (see also: git help tutorial)\n   clone      Clone a repository into a new directory\n   init       Create an empty Git repository or reinitialize an existing one\n\nwork on the current change (see also: git help everyday)\n   add        Add file contents to the index\n   mv         Move or rename a file, a directory, or a symlink\n   restore    Restore working tree files\n   rm         Remove files from the working tree and from the index\n\nexamine the history and state (see also: git help revisions)\n   bisect     Use binary search to find the commit that introduced a bug\n   diff       Show changes between commits, commit and working tree, etc\n   grep       Print lines matching a pattern\n   log        Show commit logs\n   show       Show various types of objects\n   status     Show the working tree status\n\ngrow, mark and tweak your common history\n   backfill   Download missing objects in a partial clone\n   branch     List, create, or delete branches\n   commit     Record changes to the repository\n   merge      Join two or more development histories together\n   rebase     Reapply commits on top of another base tip\n   reset      Reset current HEAD to the specified state\n   switch     Switch branches\n   tag        Create, list, delete or verify a tag object signed with GPG\n\ncollaborate (see also: git help workflows)\n   fetch      Download objects and refs from another repository\n   pull       Fetch from and integrate with another repository or a local branch\n   push       Update remote refs along with associated objects\n\n'git help -a' and 'git help -g' list available subcommands and some\nconcept guides. See 'git help <command>' or 'git help <concept>'\nto read about a specific subcommand or concept.\nSee 'git help git' for an overview of the system.\n""
[0m16:42:09.582631 [debug] [MainThread]: STDERR: "b''"
[0m16:42:09.582943 [info ] [MainThread]:  - git [[32mOK found[0m]

[0m16:42:09.583524 [info ] [MainThread]: Connection:
[0m16:42:09.584331 [info ] [MainThread]:   account: https://app.snowflake.com/alation/alation-partner-aws-us-west-2/#/data/databases/LOGAN-DATA
[0m16:42:09.585060 [info ] [MainThread]:   user: LD_USER
[0m16:42:09.585864 [info ] [MainThread]:   database: LOGAN_DATA
[0m16:42:09.586440 [info ] [MainThread]:   warehouse: LOAD_WH
[0m16:42:09.587004 [info ] [MainThread]:   role: LOGAN_DATA_ROLE
[0m16:42:09.587416 [info ] [MainThread]:   schema: Navanita_fivetran_dbt
[0m16:42:09.587912 [info ] [MainThread]:   authenticator: None
[0m16:42:09.588311 [info ] [MainThread]:   oauth_client_id: None
[0m16:42:09.588618 [info ] [MainThread]:   query_tag: None
[0m16:42:09.588909 [info ] [MainThread]:   client_session_keep_alive: False
[0m16:42:09.589199 [info ] [MainThread]:   host: None
[0m16:42:09.589536 [info ] [MainThread]:   port: None
[0m16:42:09.589828 [info ] [MainThread]:   proxy_host: None
[0m16:42:09.590356 [info ] [MainThread]:   proxy_port: None
[0m16:42:09.591081 [info ] [MainThread]:   protocol: None
[0m16:42:09.591832 [info ] [MainThread]:   connect_retries: 1
[0m16:42:09.592243 [info ] [MainThread]:   connect_timeout: None
[0m16:42:09.592731 [info ] [MainThread]:   retry_on_database_errors: False
[0m16:42:09.593242 [info ] [MainThread]:   retry_all: False
[0m16:42:09.593643 [info ] [MainThread]:   insecure_mode: False
[0m16:42:09.594294 [info ] [MainThread]:   reuse_connections: True
[0m16:42:09.595150 [info ] [MainThread]: Registered adapter: snowflake=1.9.2
[0m16:42:09.900697 [debug] [MainThread]: Acquiring new snowflake connection 'debug'
[0m16:42:09.974137 [debug] [MainThread]: Using snowflake connection "debug"
[0m16:42:09.974524 [debug] [MainThread]: On debug: select 1 as id
[0m16:42:09.974771 [debug] [MainThread]: Opening a new connection, currently in state init
[0m16:47:07.830423 [error] [MainThread]: Encountered an error:

[0m16:47:07.841259 [error] [MainThread]: Traceback (most recent call last):
  File "C:\Users\KIIT\AppData\Local\Programs\Python\Python313\Lib\site-packages\snowflake\connector\vendored\urllib3\connection.py", line 174, in _new_conn
    conn = connection.create_connection(
        (self._dns_host, self.port), self.timeout, **extra_kw
    )
  File "C:\Users\KIIT\AppData\Local\Programs\Python\Python313\Lib\site-packages\snowflake\connector\vendored\urllib3\util\connection.py", line 79, in create_connection
    for res in socket.getaddrinfo(host, port, family, socket.SOCK_STREAM):
               ~~~~~~~~~~~~~~~~~~^^^^^^^^^^^^^^^^^^^^^^^^^^^^^^^^^^^^^^^^
  File "C:\Users\KIIT\AppData\Local\Programs\Python\Python313\Lib\socket.py", line 977, in getaddrinfo
    for res in _socket.getaddrinfo(host, port, family, type, proto, flags):
               ~~~~~~~~~~~~~~~~~~~^^^^^^^^^^^^^^^^^^^^^^^^^^^^^^^^^^^^^^^^
socket.gaierror: [Errno 11001] getaddrinfo failed

During handling of the above exception, another exception occurred:

Traceback (most recent call last):
  File "C:\Users\KIIT\AppData\Local\Programs\Python\Python313\Lib\site-packages\dbt\cli\requires.py", line 153, in wrapper
    result, success = func(*args, **kwargs)
                      ~~~~^^^^^^^^^^^^^^^^^
  File "C:\Users\KIIT\AppData\Local\Programs\Python\Python313\Lib\site-packages\dbt\cli\requires.py", line 103, in wrapper
    return func(*args, **kwargs)
  File "C:\Users\KIIT\AppData\Local\Programs\Python\Python313\Lib\site-packages\dbt\cli\main.py", line 414, in debug
    results = task.run()
  File "C:\Users\KIIT\AppData\Local\Programs\Python\Python313\Lib\site-packages\dbt\task\debug.py", line 144, in run
    connection_status = self.test_connection()
  File "C:\Users\KIIT\AppData\Local\Programs\Python\Python313\Lib\site-packages\dbt\task\debug.py", line 465, in test_connection
    connection_result = self.attempt_connection(self.profile)
  File "C:\Users\KIIT\AppData\Local\Programs\Python\Python313\Lib\site-packages\dbt\task\debug.py", line 443, in attempt_connection
    adapter.debug_query()
    ~~~~~~~~~~~~~~~~~~~^^
  File "C:\Users\KIIT\AppData\Local\Programs\Python\Python313\Lib\site-packages\dbt\adapters\snowflake\impl.py", line 436, in debug_query
    self.execute("select 1 as id")
    ~~~~~~~~~~~~^^^^^^^^^^^^^^^^^^
  File "C:\Users\KIIT\AppData\Local\Programs\Python\Python313\Lib\site-packages\dbt\adapters\base\impl.py", line 404, in execute
    return self.connections.execute(sql=sql, auto_begin=auto_begin, fetch=fetch, limit=limit)
           ~~~~~~~~~~~~~~~~~~~~~~~~^^^^^^^^^^^^^^^^^^^^^^^^^^^^^^^^^^^^^^^^^^^^^^^^^^^^^^^^^^
  File "C:\Users\KIIT\AppData\Local\Programs\Python\Python313\Lib\site-packages\dbt\adapters\snowflake\connections.py", line 514, in execute
    _, cursor = self.add_query(sql, auto_begin)
                ~~~~~~~~~~~~~~^^^^^^^^^^^^^^^^^
  File "C:\Users\KIIT\AppData\Local\Programs\Python\Python313\Lib\site-packages\dbt\adapters\snowflake\connections.py", line 551, in add_query
    connection, cursor = self._add_standard_queries(
                         ~~~~~~~~~~~~~~~~~~~~~~~~~~^
        stripped_queries,
        ^^^^^^^^^^^^^^^^^
    ...<2 lines>...
        abridge_sql_log=abridge_sql_log,
        ^^^^^^^^^^^^^^^^^^^^^^^^^^^^^^^^
    )
    ^
  File "C:\Users\KIIT\AppData\Local\Programs\Python\Python313\Lib\site-packages\dbt\adapters\snowflake\connections.py", line 607, in _add_standard_queries
    connection, cursor = self.add_standard_query(query, **kwargs)
                         ~~~~~~~~~~~~~~~~~~~~~~~^^^^^^^^^^^^^^^^^
  File "C:\Users\KIIT\AppData\Local\Programs\Python\Python313\Lib\site-packages\dbt\adapters\snowflake\connections.py", line 525, in add_standard_query
    return super().add_query(self._add_query_comment(sql), **kwargs)
           ~~~~~~~~~~~~~~~~~^^^^^^^^^^^^^^^^^^^^^^^^^^^^^^^^^^^^^^^^
  File "C:\Users\KIIT\AppData\Local\Programs\Python\Python313\Lib\site-packages\dbt\adapters\sql\connections.py", line 146, in add_query
    cursor = connection.handle.cursor()
             ^^^^^^^^^^^^^^^^^
  File "C:\Users\KIIT\AppData\Local\Programs\Python\Python313\Lib\site-packages\dbt\adapters\contracts\connection.py", line 96, in handle
    self._handle.resolve(self)
    ~~~~~~~~~~~~~~~~~~~~^^^^^^
  File "C:\Users\KIIT\AppData\Local\Programs\Python\Python313\Lib\site-packages\dbt\adapters\contracts\connection.py", line 120, in resolve
    return self.opener(connection)
           ~~~~~~~~~~~^^^^^^^^^^^^
  File "C:\Users\KIIT\AppData\Local\Programs\Python\Python313\Lib\site-packages\dbt\adapters\snowflake\connections.py", line 420, in open
    return cls.retry_connection(
           ~~~~~~~~~~~~~~~~~~~~^
        connection,
        ^^^^^^^^^^^
    ...<4 lines>...
        retryable_exceptions=retryable_exceptions,
        ^^^^^^^^^^^^^^^^^^^^^^^^^^^^^^^^^^^^^^^^^^
    )
    ^
  File "C:\Users\KIIT\AppData\Local\Programs\Python\Python313\Lib\site-packages\dbt\adapters\base\connections.py", line 237, in retry_connection
    connection.handle = connect()
                        ~~~~~~~^^
  File "C:\Users\KIIT\AppData\Local\Programs\Python\Python313\Lib\site-packages\dbt\adapters\snowflake\connections.py", line 380, in connect
    handle = snowflake.connector.connect(
        account=creds.account,
    ...<9 lines>...
        **creds.auth_args(),
    )
  File "C:\Users\KIIT\AppData\Local\Programs\Python\Python313\Lib\site-packages\snowflake\connector\__init__.py", line 55, in Connect
    return SnowflakeConnection(**kwargs)
  File "C:\Users\KIIT\AppData\Local\Programs\Python\Python313\Lib\site-packages\snowflake\connector\connection.py", line 466, in __init__
    self.connect(**kwargs)
    ~~~~~~~~~~~~^^^^^^^^^^
  File "C:\Users\KIIT\AppData\Local\Programs\Python\Python313\Lib\site-packages\snowflake\connector\connection.py", line 793, in connect
    self.__open_connection()
    ~~~~~~~~~~~~~~~~~~~~~~^^
  File "C:\Users\KIIT\AppData\Local\Programs\Python\Python313\Lib\site-packages\snowflake\connector\connection.py", line 1124, in __open_connection
    self.authenticate_with_retry(self.auth_class)
    ~~~~~~~~~~~~~~~~~~~~~~~~~~~~^^^^^^^^^^^^^^^^^
  File "C:\Users\KIIT\AppData\Local\Programs\Python\Python313\Lib\site-packages\snowflake\connector\connection.py", line 1424, in authenticate_with_retry
    self._authenticate(auth_instance)
    ~~~~~~~~~~~~~~~~~~^^^^^^^^^^^^^^^
  File "C:\Users\KIIT\AppData\Local\Programs\Python\Python313\Lib\site-packages\snowflake\connector\connection.py", line 1452, in _authenticate
    auth.authenticate(
    ~~~~~~~~~~~~~~~~~^
        auth_instance=auth_instance,
        ^^^^^^^^^^^^^^^^^^^^^^^^^^^^
    ...<10 lines>...
        session_parameters=self._session_parameters,
        ^^^^^^^^^^^^^^^^^^^^^^^^^^^^^^^^^^^^^^^^^^^^
    )
    ^
  File "C:\Users\KIIT\AppData\Local\Programs\Python\Python313\Lib\site-packages\snowflake\connector\auth\_auth.py", line 270, in authenticate
    ret = self._rest._post_request(
        url,
    ...<2 lines>...
        socket_timeout=auth_instance._socket_timeout,
    )
  File "C:\Users\KIIT\AppData\Local\Programs\Python\Python313\Lib\site-packages\snowflake\connector\network.py", line 750, in _post_request
    ret = self.fetch(
        "post",
    ...<7 lines>...
        socket_timeout=socket_timeout,
    )
  File "C:\Users\KIIT\AppData\Local\Programs\Python\Python313\Lib\site-packages\snowflake\connector\network.py", line 865, in fetch
    ret = self._request_exec_wrapper(
        session, method, full_url, headers, data, retry_ctx, **kwargs
    )
  File "C:\Users\KIIT\AppData\Local\Programs\Python\Python313\Lib\site-packages\snowflake\connector\network.py", line 915, in _request_exec_wrapper
    return_object = self._request_exec(
        session=session,
    ...<6 lines>...
        **kwargs,
    )
  File "C:\Users\KIIT\AppData\Local\Programs\Python\Python313\Lib\site-packages\snowflake\connector\network.py", line 1082, in _request_exec
    raw_ret = session.request(
        method=method,
    ...<6 lines>...
        auth=SnowflakeAuth(token),
    )
  File "C:\Users\KIIT\AppData\Local\Programs\Python\Python313\Lib\site-packages\snowflake\connector\vendored\requests\sessions.py", line 589, in request
    resp = self.send(prep, **send_kwargs)
  File "C:\Users\KIIT\AppData\Local\Programs\Python\Python313\Lib\site-packages\snowflake\connector\vendored\requests\sessions.py", line 703, in send
    r = adapter.send(request, **kwargs)
  File "C:\Users\KIIT\AppData\Local\Programs\Python\Python313\Lib\site-packages\snowflake\connector\vendored\requests\adapters.py", line 486, in send
    resp = conn.urlopen(
        method=request.method,
    ...<9 lines>...
        chunked=chunked,
    )
  File "C:\Users\KIIT\AppData\Local\Programs\Python\Python313\Lib\site-packages\snowflake\connector\vendored\urllib3\connectionpool.py", line 715, in urlopen
    httplib_response = self._make_request(
        conn,
    ...<5 lines>...
        chunked=chunked,
    )
  File "C:\Users\KIIT\AppData\Local\Programs\Python\Python313\Lib\site-packages\snowflake\connector\vendored\urllib3\connectionpool.py", line 404, in _make_request
    self._validate_conn(conn)
    ~~~~~~~~~~~~~~~~~~~^^^^^^
  File "C:\Users\KIIT\AppData\Local\Programs\Python\Python313\Lib\site-packages\snowflake\connector\vendored\urllib3\connectionpool.py", line 1058, in _validate_conn
    conn.connect()
    ~~~~~~~~~~~~^^
  File "C:\Users\KIIT\AppData\Local\Programs\Python\Python313\Lib\site-packages\snowflake\connector\vendored\urllib3\connection.py", line 363, in connect
    self.sock = conn = self._new_conn()
                       ~~~~~~~~~~~~~~^^
  File "C:\Users\KIIT\AppData\Local\Programs\Python\Python313\Lib\site-packages\snowflake\connector\vendored\urllib3\connection.py", line 187, in _new_conn
    self, "Failed to establish a new connection: %s" % e
          ~~~~~~~~~~~~~~~~~~~~~~~~~~~~~~~~~~~~~~~~~~~^~~
KeyboardInterrupt

[0m16:47:07.844278 [debug] [MainThread]: Command `dbt debug` failed at 16:47:07.844120 after 299.16 seconds
[0m16:47:07.844610 [debug] [MainThread]: Connection 'debug' was properly closed.
[0m16:47:07.844895 [debug] [MainThread]: Sending event: {'category': 'dbt', 'action': 'invocation', 'label': 'end', 'context': [<snowplow_tracker.self_describing_json.SelfDescribingJson object at 0x000001D0EAAAD5B0>, <snowplow_tracker.self_describing_json.SelfDescribingJson object at 0x000001D0EAB1CEF0>, <snowplow_tracker.self_describing_json.SelfDescribingJson object at 0x000001D0EA6B79B0>]}
[0m16:47:07.845227 [debug] [MainThread]: Flushing usage events
[0m16:47:09.205010 [debug] [MainThread]: An error was encountered while trying to flush usage events
[0m16:47:50.056596 [debug] [MainThread]: Sending event: {'category': 'dbt', 'action': 'invocation', 'label': 'start', 'context': [<snowplow_tracker.self_describing_json.SelfDescribingJson object at 0x000002A6E0A41FD0>, <snowplow_tracker.self_describing_json.SelfDescribingJson object at 0x000002A6DEBCD590>, <snowplow_tracker.self_describing_json.SelfDescribingJson object at 0x000002A6E1BA7ED0>]}


============================== 16:47:50.060973 | 996fbecd-fd62-40bc-a6b4-f401c9e19d7d ==============================
[0m16:47:50.060973 [info ] [MainThread]: Running with dbt=1.9.3
[0m16:47:50.062005 [debug] [MainThread]: running dbt with arguments {'printer_width': '80', 'indirect_selection': 'eager', 'log_cache_events': 'False', 'write_json': 'True', 'partial_parse': 'True', 'cache_selected_only': 'False', 'profiles_dir': 'C:\\Users\\KIIT\\.dbt', 'fail_fast': 'False', 'warn_error': 'None', 'log_path': 'logs', 'version_check': 'True', 'debug': 'False', 'use_colors': 'True', 'use_experimental_parser': 'False', 'empty': 'None', 'quiet': 'False', 'no_print': 'None', 'log_format': 'default', 'introspect': 'True', 'static_parser': 'True', 'warn_error_options': 'WarnErrorOptions(include=[], exclude=[])', 'target_path': 'None', 'invocation_command': 'dbt debug', 'send_anonymous_usage_stats': 'True'}
[0m16:47:50.077291 [info ] [MainThread]: dbt version: 1.9.3
[0m16:47:50.077842 [info ] [MainThread]: python version: 3.13.2
[0m16:47:50.078372 [info ] [MainThread]: python path: C:\Users\KIIT\AppData\Local\Programs\Python\Python313\python.exe
[0m16:47:50.078804 [info ] [MainThread]: os info: Windows-11-10.0.22631-SP0
[0m16:47:50.766898 [info ] [MainThread]: Using profiles dir at C:\Users\KIIT\.dbt
[0m16:47:50.768055 [info ] [MainThread]: Using profiles.yml file at C:\Users\KIIT\.dbt\profiles.yml
[0m16:47:50.768817 [info ] [MainThread]: Using dbt_project.yml file at C:\Users\KIIT\Downloads\my-dbt-project\dbt_project.yml
[0m16:47:50.770198 [info ] [MainThread]: adapter type: snowflake
[0m16:47:50.770714 [info ] [MainThread]: adapter version: 1.9.2
[0m16:47:50.771294 [info ] [MainThread]: Configuration:
[0m16:47:50.772041 [info ] [MainThread]:   profiles.yml file [[32mOK found and valid[0m]
[0m16:47:50.772550 [info ] [MainThread]:   dbt_project.yml file [[31mERROR not found[0m]
[0m16:47:50.773002 [info ] [MainThread]: Required dependencies:
[0m16:47:50.773597 [debug] [MainThread]: Executing "git --help"
[0m16:47:50.820808 [debug] [MainThread]: STDOUT: "b"usage: git [-v | --version] [-h | --help] [-C <path>] [-c <name>=<value>]\n           [--exec-path[=<path>]] [--html-path] [--man-path] [--info-path]\n           [-p | --paginate | -P | --no-pager] [--no-replace-objects] [--no-lazy-fetch]\n           [--no-optional-locks] [--no-advice] [--bare] [--git-dir=<path>]\n           [--work-tree=<path>] [--namespace=<name>] [--config-env=<name>=<envvar>]\n           <command> [<args>]\n\nThese are common Git commands used in various situations:\n\nstart a working area (see also: git help tutorial)\n   clone      Clone a repository into a new directory\n   init       Create an empty Git repository or reinitialize an existing one\n\nwork on the current change (see also: git help everyday)\n   add        Add file contents to the index\n   mv         Move or rename a file, a directory, or a symlink\n   restore    Restore working tree files\n   rm         Remove files from the working tree and from the index\n\nexamine the history and state (see also: git help revisions)\n   bisect     Use binary search to find the commit that introduced a bug\n   diff       Show changes between commits, commit and working tree, etc\n   grep       Print lines matching a pattern\n   log        Show commit logs\n   show       Show various types of objects\n   status     Show the working tree status\n\ngrow, mark and tweak your common history\n   backfill   Download missing objects in a partial clone\n   branch     List, create, or delete branches\n   commit     Record changes to the repository\n   merge      Join two or more development histories together\n   rebase     Reapply commits on top of another base tip\n   reset      Reset current HEAD to the specified state\n   switch     Switch branches\n   tag        Create, list, delete or verify a tag object signed with GPG\n\ncollaborate (see also: git help workflows)\n   fetch      Download objects and refs from another repository\n   pull       Fetch from and integrate with another repository or a local branch\n   push       Update remote refs along with associated objects\n\n'git help -a' and 'git help -g' list available subcommands and some\nconcept guides. See 'git help <command>' or 'git help <concept>'\nto read about a specific subcommand or concept.\nSee 'git help git' for an overview of the system.\n""
[0m16:47:50.821259 [debug] [MainThread]: STDERR: "b''"
[0m16:47:50.821575 [info ] [MainThread]:  - git [[32mOK found[0m]

[0m16:47:50.822171 [info ] [MainThread]: Connection:
[0m16:47:50.822965 [info ] [MainThread]:   account: https://app.snowflake.com/alation/alation-partner-aws-us-west-2/#/data/databases/LOGAN-DATA
[0m16:47:50.823657 [info ] [MainThread]:   user: LD_USER
[0m16:47:50.824450 [info ] [MainThread]:   database: LOGAN_DATA
[0m16:47:50.825099 [info ] [MainThread]:   warehouse: LOAD_WH
[0m16:47:50.825664 [info ] [MainThread]:   role: LOGAN_DATA_ROLE
[0m16:47:50.826332 [info ] [MainThread]:   schema: Navanita_fivetran_dbt
[0m16:47:50.827007 [info ] [MainThread]:   authenticator: None
[0m16:47:50.827549 [info ] [MainThread]:   oauth_client_id: None
[0m16:47:50.828150 [info ] [MainThread]:   query_tag: None
[0m16:47:50.828644 [info ] [MainThread]:   client_session_keep_alive: False
[0m16:47:50.829176 [info ] [MainThread]:   host: None
[0m16:47:50.829831 [info ] [MainThread]:   port: None
[0m16:47:50.830509 [info ] [MainThread]:   proxy_host: None
[0m16:47:50.831053 [info ] [MainThread]:   proxy_port: None
[0m16:47:50.831594 [info ] [MainThread]:   protocol: None
[0m16:47:50.832141 [info ] [MainThread]:   connect_retries: 1
[0m16:47:50.832839 [info ] [MainThread]:   connect_timeout: None
[0m16:47:50.833460 [info ] [MainThread]:   retry_on_database_errors: False
[0m16:47:50.833875 [info ] [MainThread]:   retry_all: False
[0m16:47:50.834270 [info ] [MainThread]:   insecure_mode: False
[0m16:47:50.834891 [info ] [MainThread]:   reuse_connections: True
[0m16:47:50.836236 [info ] [MainThread]: Registered adapter: snowflake=1.9.2
[0m16:47:51.133891 [debug] [MainThread]: Acquiring new snowflake connection 'debug'
[0m16:47:51.215072 [debug] [MainThread]: Using snowflake connection "debug"
[0m16:47:51.215432 [debug] [MainThread]: On debug: select 1 as id
[0m16:47:51.215661 [debug] [MainThread]: Opening a new connection, currently in state init
[0m16:48:15.993737 [error] [MainThread]: Encountered an error:

[0m16:48:16.005107 [error] [MainThread]: Traceback (most recent call last):
  File "C:\Users\KIIT\AppData\Local\Programs\Python\Python313\Lib\site-packages\snowflake\connector\vendored\urllib3\connection.py", line 174, in _new_conn
    conn = connection.create_connection(
        (self._dns_host, self.port), self.timeout, **extra_kw
    )
  File "C:\Users\KIIT\AppData\Local\Programs\Python\Python313\Lib\site-packages\snowflake\connector\vendored\urllib3\util\connection.py", line 79, in create_connection
    for res in socket.getaddrinfo(host, port, family, socket.SOCK_STREAM):
               ~~~~~~~~~~~~~~~~~~^^^^^^^^^^^^^^^^^^^^^^^^^^^^^^^^^^^^^^^^
  File "C:\Users\KIIT\AppData\Local\Programs\Python\Python313\Lib\socket.py", line 977, in getaddrinfo
    for res in _socket.getaddrinfo(host, port, family, type, proto, flags):
               ~~~~~~~~~~~~~~~~~~~^^^^^^^^^^^^^^^^^^^^^^^^^^^^^^^^^^^^^^^^
socket.gaierror: [Errno 11001] getaddrinfo failed

During handling of the above exception, another exception occurred:

Traceback (most recent call last):
  File "C:\Users\KIIT\AppData\Local\Programs\Python\Python313\Lib\site-packages\dbt\cli\requires.py", line 153, in wrapper
    result, success = func(*args, **kwargs)
                      ~~~~^^^^^^^^^^^^^^^^^
  File "C:\Users\KIIT\AppData\Local\Programs\Python\Python313\Lib\site-packages\dbt\cli\requires.py", line 103, in wrapper
    return func(*args, **kwargs)
  File "C:\Users\KIIT\AppData\Local\Programs\Python\Python313\Lib\site-packages\dbt\cli\main.py", line 414, in debug
    results = task.run()
  File "C:\Users\KIIT\AppData\Local\Programs\Python\Python313\Lib\site-packages\dbt\task\debug.py", line 144, in run
    connection_status = self.test_connection()
  File "C:\Users\KIIT\AppData\Local\Programs\Python\Python313\Lib\site-packages\dbt\task\debug.py", line 465, in test_connection
    connection_result = self.attempt_connection(self.profile)
  File "C:\Users\KIIT\AppData\Local\Programs\Python\Python313\Lib\site-packages\dbt\task\debug.py", line 443, in attempt_connection
    adapter.debug_query()
    ~~~~~~~~~~~~~~~~~~~^^
  File "C:\Users\KIIT\AppData\Local\Programs\Python\Python313\Lib\site-packages\dbt\adapters\snowflake\impl.py", line 436, in debug_query
    self.execute("select 1 as id")
    ~~~~~~~~~~~~^^^^^^^^^^^^^^^^^^
  File "C:\Users\KIIT\AppData\Local\Programs\Python\Python313\Lib\site-packages\dbt\adapters\base\impl.py", line 404, in execute
    return self.connections.execute(sql=sql, auto_begin=auto_begin, fetch=fetch, limit=limit)
           ~~~~~~~~~~~~~~~~~~~~~~~~^^^^^^^^^^^^^^^^^^^^^^^^^^^^^^^^^^^^^^^^^^^^^^^^^^^^^^^^^^
  File "C:\Users\KIIT\AppData\Local\Programs\Python\Python313\Lib\site-packages\dbt\adapters\snowflake\connections.py", line 514, in execute
    _, cursor = self.add_query(sql, auto_begin)
                ~~~~~~~~~~~~~~^^^^^^^^^^^^^^^^^
  File "C:\Users\KIIT\AppData\Local\Programs\Python\Python313\Lib\site-packages\dbt\adapters\snowflake\connections.py", line 551, in add_query
    connection, cursor = self._add_standard_queries(
                         ~~~~~~~~~~~~~~~~~~~~~~~~~~^
        stripped_queries,
        ^^^^^^^^^^^^^^^^^
    ...<2 lines>...
        abridge_sql_log=abridge_sql_log,
        ^^^^^^^^^^^^^^^^^^^^^^^^^^^^^^^^
    )
    ^
  File "C:\Users\KIIT\AppData\Local\Programs\Python\Python313\Lib\site-packages\dbt\adapters\snowflake\connections.py", line 607, in _add_standard_queries
    connection, cursor = self.add_standard_query(query, **kwargs)
                         ~~~~~~~~~~~~~~~~~~~~~~~^^^^^^^^^^^^^^^^^
  File "C:\Users\KIIT\AppData\Local\Programs\Python\Python313\Lib\site-packages\dbt\adapters\snowflake\connections.py", line 525, in add_standard_query
    return super().add_query(self._add_query_comment(sql), **kwargs)
           ~~~~~~~~~~~~~~~~~^^^^^^^^^^^^^^^^^^^^^^^^^^^^^^^^^^^^^^^^
  File "C:\Users\KIIT\AppData\Local\Programs\Python\Python313\Lib\site-packages\dbt\adapters\sql\connections.py", line 146, in add_query
    cursor = connection.handle.cursor()
             ^^^^^^^^^^^^^^^^^
  File "C:\Users\KIIT\AppData\Local\Programs\Python\Python313\Lib\site-packages\dbt\adapters\contracts\connection.py", line 96, in handle
    self._handle.resolve(self)
    ~~~~~~~~~~~~~~~~~~~~^^^^^^
  File "C:\Users\KIIT\AppData\Local\Programs\Python\Python313\Lib\site-packages\dbt\adapters\contracts\connection.py", line 120, in resolve
    return self.opener(connection)
           ~~~~~~~~~~~^^^^^^^^^^^^
  File "C:\Users\KIIT\AppData\Local\Programs\Python\Python313\Lib\site-packages\dbt\adapters\snowflake\connections.py", line 420, in open
    return cls.retry_connection(
           ~~~~~~~~~~~~~~~~~~~~^
        connection,
        ^^^^^^^^^^^
    ...<4 lines>...
        retryable_exceptions=retryable_exceptions,
        ^^^^^^^^^^^^^^^^^^^^^^^^^^^^^^^^^^^^^^^^^^
    )
    ^
  File "C:\Users\KIIT\AppData\Local\Programs\Python\Python313\Lib\site-packages\dbt\adapters\base\connections.py", line 237, in retry_connection
    connection.handle = connect()
                        ~~~~~~~^^
  File "C:\Users\KIIT\AppData\Local\Programs\Python\Python313\Lib\site-packages\dbt\adapters\snowflake\connections.py", line 380, in connect
    handle = snowflake.connector.connect(
        account=creds.account,
    ...<9 lines>...
        **creds.auth_args(),
    )
  File "C:\Users\KIIT\AppData\Local\Programs\Python\Python313\Lib\site-packages\snowflake\connector\__init__.py", line 55, in Connect
    return SnowflakeConnection(**kwargs)
  File "C:\Users\KIIT\AppData\Local\Programs\Python\Python313\Lib\site-packages\snowflake\connector\connection.py", line 466, in __init__
    self.connect(**kwargs)
    ~~~~~~~~~~~~^^^^^^^^^^
  File "C:\Users\KIIT\AppData\Local\Programs\Python\Python313\Lib\site-packages\snowflake\connector\connection.py", line 793, in connect
    self.__open_connection()
    ~~~~~~~~~~~~~~~~~~~~~~^^
  File "C:\Users\KIIT\AppData\Local\Programs\Python\Python313\Lib\site-packages\snowflake\connector\connection.py", line 1124, in __open_connection
    self.authenticate_with_retry(self.auth_class)
    ~~~~~~~~~~~~~~~~~~~~~~~~~~~~^^^^^^^^^^^^^^^^^
  File "C:\Users\KIIT\AppData\Local\Programs\Python\Python313\Lib\site-packages\snowflake\connector\connection.py", line 1424, in authenticate_with_retry
    self._authenticate(auth_instance)
    ~~~~~~~~~~~~~~~~~~^^^^^^^^^^^^^^^
  File "C:\Users\KIIT\AppData\Local\Programs\Python\Python313\Lib\site-packages\snowflake\connector\connection.py", line 1452, in _authenticate
    auth.authenticate(
    ~~~~~~~~~~~~~~~~~^
        auth_instance=auth_instance,
        ^^^^^^^^^^^^^^^^^^^^^^^^^^^^
    ...<10 lines>...
        session_parameters=self._session_parameters,
        ^^^^^^^^^^^^^^^^^^^^^^^^^^^^^^^^^^^^^^^^^^^^
    )
    ^
  File "C:\Users\KIIT\AppData\Local\Programs\Python\Python313\Lib\site-packages\snowflake\connector\auth\_auth.py", line 270, in authenticate
    ret = self._rest._post_request(
        url,
    ...<2 lines>...
        socket_timeout=auth_instance._socket_timeout,
    )
  File "C:\Users\KIIT\AppData\Local\Programs\Python\Python313\Lib\site-packages\snowflake\connector\network.py", line 750, in _post_request
    ret = self.fetch(
        "post",
    ...<7 lines>...
        socket_timeout=socket_timeout,
    )
  File "C:\Users\KIIT\AppData\Local\Programs\Python\Python313\Lib\site-packages\snowflake\connector\network.py", line 865, in fetch
    ret = self._request_exec_wrapper(
        session, method, full_url, headers, data, retry_ctx, **kwargs
    )
  File "C:\Users\KIIT\AppData\Local\Programs\Python\Python313\Lib\site-packages\snowflake\connector\network.py", line 915, in _request_exec_wrapper
    return_object = self._request_exec(
        session=session,
    ...<6 lines>...
        **kwargs,
    )
  File "C:\Users\KIIT\AppData\Local\Programs\Python\Python313\Lib\site-packages\snowflake\connector\network.py", line 1082, in _request_exec
    raw_ret = session.request(
        method=method,
    ...<6 lines>...
        auth=SnowflakeAuth(token),
    )
  File "C:\Users\KIIT\AppData\Local\Programs\Python\Python313\Lib\site-packages\snowflake\connector\vendored\requests\sessions.py", line 589, in request
    resp = self.send(prep, **send_kwargs)
  File "C:\Users\KIIT\AppData\Local\Programs\Python\Python313\Lib\site-packages\snowflake\connector\vendored\requests\sessions.py", line 703, in send
    r = adapter.send(request, **kwargs)
  File "C:\Users\KIIT\AppData\Local\Programs\Python\Python313\Lib\site-packages\snowflake\connector\vendored\requests\adapters.py", line 486, in send
    resp = conn.urlopen(
        method=request.method,
    ...<9 lines>...
        chunked=chunked,
    )
  File "C:\Users\KIIT\AppData\Local\Programs\Python\Python313\Lib\site-packages\snowflake\connector\vendored\urllib3\connectionpool.py", line 715, in urlopen
    httplib_response = self._make_request(
        conn,
    ...<5 lines>...
        chunked=chunked,
    )
  File "C:\Users\KIIT\AppData\Local\Programs\Python\Python313\Lib\site-packages\snowflake\connector\vendored\urllib3\connectionpool.py", line 404, in _make_request
    self._validate_conn(conn)
    ~~~~~~~~~~~~~~~~~~~^^^^^^
  File "C:\Users\KIIT\AppData\Local\Programs\Python\Python313\Lib\site-packages\snowflake\connector\vendored\urllib3\connectionpool.py", line 1058, in _validate_conn
    conn.connect()
    ~~~~~~~~~~~~^^
  File "C:\Users\KIIT\AppData\Local\Programs\Python\Python313\Lib\site-packages\snowflake\connector\vendored\urllib3\connection.py", line 363, in connect
    self.sock = conn = self._new_conn()
                       ~~~~~~~~~~~~~~^^
  File "C:\Users\KIIT\AppData\Local\Programs\Python\Python313\Lib\site-packages\snowflake\connector\vendored\urllib3\connection.py", line 187, in _new_conn
    self, "Failed to establish a new connection: %s" % e
          ~~~~~~~~~~~~~~~~~~~~~~~~~~~~~~~~~~~~~~~~~~~^~~
KeyboardInterrupt

[0m16:48:16.009323 [debug] [MainThread]: Command `dbt debug` failed at 16:48:16.008847 after 26.11 seconds
[0m16:48:16.009822 [debug] [MainThread]: Connection 'debug' was properly closed.
[0m16:48:16.010157 [debug] [MainThread]: Sending event: {'category': 'dbt', 'action': 'invocation', 'label': 'end', 'context': [<snowplow_tracker.self_describing_json.SelfDescribingJson object at 0x000002A6830BDA70>, <snowplow_tracker.self_describing_json.SelfDescribingJson object at 0x000002A68312D130>, <snowplow_tracker.self_describing_json.SelfDescribingJson object at 0x000002A682CC7CE0>]}
[0m16:48:16.010551 [debug] [MainThread]: Flushing usage events
[0m16:48:17.992459 [debug] [MainThread]: An error was encountered while trying to flush usage events
